Workbook

Sheet Leggimi
A1: Modello di sostenibilità del debito pubblico — Sezione 1, programma Quarto Stato
A3: Equazione: d(t) = d(t-1) × (1+i) / (1+g) − s + SF
A4: d = debito/PIL; i = tasso implicito (interessi / debito dell'anno precedente); g = crescita del PIL nominale; s = saldo primario; SF = aggiustamento stock-flussi.
A5: Avanzo di stabilizzazione: s* = d(t-1) × (i − g) / (1+g) + SF
A7: Come si usa
A8: 1. I dati 2025-2029 del foglio Ipotesi riproducono il quadro tendenziale del DPFP 2026 (2 ottobre 2026). Il tasso implicito e lo stock-flussi sono ricavati dai dati ufficiali, non ipotizzati.
A9: 2. Le leve di scenario sono le celle gialle del foglio Ipotesi (righe 13-20). Modificandole, il foglio Scenari si ricalcola.
A10: 3. Dal 2030 il DPFP non fornisce previsioni: i valori 2030-2032 sono ipotesi dichiarate (cella per cella, colonna J).
A12: Codice colori
A13: Testo blu = dato immesso (fonte ufficiale o ipotesi). Testo nero = formula. Fondo giallo = leva di scenario modificabile.
A15: Limiti del modello
A16: Lo scenario crescita non ricalcola l'effetto della maggiore crescita sul saldo primario (entrate più alte): sottostima il beneficio.
... A18: Gli scenari partono dal quadro tendenziale, che non include la clausola di salvaguardia nazionale per difesa ed energia (quadro programmatico: debito 136,6% nel 2029).

Sheet Ipotesi
A1: Ipotesi e dati di base — quadro tendenziale DPFP 2026
A3: Variabile | B3: 2025 | C3: 2026 | D3: 2027 | E3: 2028 | F3: 2029 | G3: 2030 | H3: 2031 | I3: 2032 | J3: Fonte / nota
A4: Debito/PIL (DPFP, tendenziale) | B4: 1.367 | C4: 1.381 | D4: 1.384 | E4: 1.377 | F4: 1.363 | J4: ISTAT (22/9/2026) per il 2025; DPFP 2026 tendenziale per 2026-2029 (138,1 / 138,4 / 137,7 / 136,3). Nessuna previsione ufficiale oltre il 2029.
A5: Crescita PIL nominale (g) | C5: 0.027 | D5: 0.029 | E5: 0.027 | F5: 0.026 | G5: 0.026 | H5: 0.026 | I5: 0.026 | J5: DPFP 2026, quadro tendenziale. 2030-2032: ipotesi, crescita nominale invariata al livello 2029.
A6: Indebitamento netto (% PIL) | C6: 0.029 | D6: 0.029 | E6: 0.027 | F6: 0.022 | J6: DPFP 2026, quadro tendenziale (2,9 / 2,9 / 2,7 / 2,2).
A7: Saldo primario (s, % PIL) | C7: 0.012 | D7: 0.014 | E7: 0.019 | F7: 0.025 | G7: 0.025 | H7: 0.025 | I7: 0.025 | J7: DPFP 2026: 1,2 (2026) e 2,5 (2029). 2027-2028 ricavati: indebitamento tendenziale + interessi del quadro programmatico (4,3 e 4,6). Da verificare sulle tavole del DPFP. 2030-2032: ipotesi, saldo costante.
A8: Spesa per interessi (% PIL) | C8: =C6+C7 -> 0.041 | D8: =D6+D7 -> 0.043 | E8: =E6+E7 -> 0.046 | F8: =F6+F7 -> 0.047 | J8: Ricavata: indebitamento netto + saldo primario. Banca d'Italia (audizione 12/10/2026) indica 4,2% nel 2026 e 4,6% nel 2028-29 nel quadro programmatico.
A9: Tasso implicito sul debito (i) | C9: =C8*(1+C5)/B4 -> 0.030802487 | D9: =D8*(1+D5)/C4 -> 0.032039826 | E9: =E8*(1+E5)/D4 -> 0.034134393 | F9: =F8*(1+F5)/E4 -> 0.035019608 | G9: =$F$9 -> 0.035019608 | H9: =$F$9 -> 0.035019608 | I9: =$F$9 -> 0.035019608 | J9: Ricavato: interessi(t) × (1+g) / debito(t-1). 2030-2032: ipotesi, invariato al 2029 (vedi leva tassi per lo stress).
A10: Aggiustamento stock-flussi (SF, % PIL) | C10: =C4-B4*(1+C9)/(1+C5)+C7 -> 0.020938656 | D10: =D4-C4*(1+D9)/(1+D5)+D7 -> 0.012920311 | E10: =E4-D4*(1+E9)/(1+E5)+E7 -> 0.0023855891 | F10: =F4-E4*(1+F9)/(1+F5)+F7 -> -0.0011052632 | G10: 0 | H10: 0 | I10: 0 | J10: Ricavato come residuo, così il modello riproduce esattamente il debito DPFP. 2030-2032: ipotesi, zero (effetti di cassa del Superbonus esauriti).
A12: Leve di scenario
A13: Avanzo primario aggiuntivo del programma (% PIL) | B13: 0.0027 | J13: Dato del programma Quarto Stato: margine di 3,9 mld (0,18% PIL) + 25% del gettito extra certificato (0,09% PIL). Da confermare sul business plan.
A14: Anno di avvio avanzo aggiuntivo | B14: 2028 | J14: Ipotesi: primo bilancio pienamente impostato dal nuovo governo.
A15: Crescita nominale aggiuntiva (p.p.) | B15: 0.003 | J15: Ipotesi di scenario, da sostituire con stima basata su moltiplicatori pubblicati (Banca d'Italia, UPB, MEF).
A16: Anno di avvio crescita aggiuntiva | B16: 2029 | J16: Ipotesi.
A17: Shock sul tasso marginale di emissione (p.p.) | B17: 0.01 | J17: Ipotesi di stress: +1 punto sui rendimenti di nuova emissione.
A18: Anno di avvio shock | B18: 2028 | J18: Ipotesi.
A19: Vita media residua del debito (anni) | B19: 7.9 | J19: Ordine di grandezza riportato per i titoli di Stato; da verificare sull'ultimo Supplemento Finanza pubblica della Banca d'Italia.
A20: Quota di debito rifinanziata ogni anno | B20: =1/B19 -> 0.12658228 | J20: Formula: 1 / vita media residua. Approssimazione: ignora il debito nuovo da disavanzo.

Sheet Scenari
A1: Scenari del rapporto debito/PIL, 2026-2032
A3: Anno | B3: 2025 | C3: 2026 | D3: 2027 | E3: 2028 | F3: 2029 | G3: 2030 | H3: 2031 | I3: 2032
A4: 1. Tendenziale (DPFP 2026 esteso al 2032)
A5: Debito/PIL inizio anno | C5: =Ipotesi!$B$4 -> 1.367 | D5: =C10 -> 1.381 | E5: =D10 -> 1.384 | F5: =E10 -> 1.377 | G5: =F10 -> 1.363 | H5: =G10 -> 1.3499822 | I5: =H10 -> 1.3368499
A6: Crescita nominale (g) | C6: =Ipotesi!C5 -> 0.027 | D6: =Ipotesi!D5 -> 0.029 | E6: =Ipotesi!E5 -> 0.027 | F6: =Ipotesi!F5 -> 0.026 | G6: =Ipotesi!G5 -> 0.026 | H6: =Ipotesi!H5 -> 0.026 | I6: =Ipotesi!I5 -> 0.026
A7: Tasso implicito (i) | C7: =Ipotesi!C9 -> 0.030802487 | D7: =Ipotesi!D9 -> 0.032039826 | E7: =Ipotesi!E9 -> 0.034134393 | F7: =Ipotesi!F9 -> 0.035019608 | G7: =Ipotesi!G9 -> 0.035019608 | H7: =Ipotesi!H9 -> 0.035019608 | I7: =Ipotesi!I9 -> 0.035019608
A8: Saldo primario (s) | C8: =Ipotesi!C7 -> 0.012 | D8: =Ipotesi!D7 -> 0.014 | E8: =Ipotesi!E7 -> 0.019 | F8: =Ipotesi!F7 -> 0.025 | G8: =Ipotesi!G7 -> 0.025 | H8: =Ipotesi!H7 -> 0.025 | I8: =Ipotesi!I7 -> 0.025
A9: Stock-flussi (SF) | C9: =Ipotesi!C10 -> 0.020938656 | D9: =Ipotesi!D10 -> 0.012920311 | E9: =Ipotesi!E10 -> 0.0023855891 | F9: =Ipotesi!F10 -> -0.0011052632 | G9: =Ipotesi!G10 -> 0 | H9: =Ipotesi!H10 -> 0 | I9: =Ipotesi!I10 -> 0
A10: Debito/PIL fine anno | C10: =C5*(1+C7)/(1+C6)-C8+C9 -> 1.381 | D10: =D5*(1+D7)/(1+D6)-D8+D9 -> 1.384 | E10: =E5*(1+E7)/(1+E6)-E8+E9 -> 1.377 | F10: =F5*(1+F7)/(1+F6)-F8+F9 -> 1.363 | G10: =G5*(1+G7)/(1+G6)-G8+G9 -> 1.3499822 | H10: =H5*(1+H7)/(1+H6)-H8+H9 -> 1.3368499 | I10: =I5*(1+I7)/(1+I6)-I8+I9 -> 1.3236022
A11: Avanzo di stabilizzazione (s*) | C11: =C5*(C7-C6)/(1+C6)+C9 -> 0.026 | D11: =D5*(D7-D6)/(1+D6)+D9 -> 0.017 | E11: =E5*(E7-E6)/(1+E6)+E9 -> 0.012 | F11: =F5*(F7-F6)/(1+F6)+F9 -> 0.011 | G11: =G5*(G7-G6)/(1+G6)+G9 -> 0.011982189 | H11: =H5*(H7-H6)/(1+H6)+H9 -> 0.011867748 | I11: =I5*(I7-I6)/(1+I6)+I9 -> 0.011752302
A12: Scarto dal tendenziale (p.p.) | C12: =(C10-C$10)*100 -> 0 | D12: =(D10-D$10)*100 -> 0 | E12: =(E10-E$10)*100 -> 0 | F12: =(F10-F$10)*100 -> 0 | G12: =(G10-G$10)*100 -> 0 | H12: =(H10-H$10)*100 -> 0 | I12: =(I10-I$10)*100 -> 0
A15: 2. Programma (avanzo primario aggiuntivo)
A16: Debito/PIL inizio anno | C16: =Ipotesi!$B$4 -> 1.367 | D16: =C21 -> 1.381 | E16: =D21 -> 1.384 | F16: =E21 -> 1.3743 | G16: =F21 -> 1.3575763 | H16: =G21 -> 1.3418108 | I16: =H21 -> 1.3259067
A17: Crescita nominale (g) | C17: =Ipotesi!C5 -> 0.027 | D17: =Ipotesi!D5 -> 0.029 | E17: =Ipotesi!E5 -> 0.027 | F17: =Ipotesi!F5 -> 0.026 | G17: =Ipotesi!G5 -> 0.026 | H17: =Ipotesi!H5 -> 0.026 | I17: =Ipotesi!I5 -> 0.026
A18: Tasso implicito (i) | C18: =Ipotesi!C9 -> 0.030802487 | D18: =Ipotesi!D9 -> 0.032039826 | E18: =Ipotesi!E9 -> 0.034134393 | F18: =Ipotesi!F9 -> 0.035019608 | G18: =Ipotesi!G9 -> 0.035019608 | H18: =Ipotesi!H9 -> 0.035019608 | I18: =Ipotesi!I9 -> 0.035019608
A19: Saldo primario (s) | C19: =Ipotesi!C7+IF(C$3>=Ipotesi!$B$14,Ipotesi!$B$13,0) -> 0.012 | D19: =Ipotesi!D7+IF(D$3>=Ipotesi!$B$14,Ipotesi!$B$13,0) -> 0.014 | E19: =Ipotesi!E7+IF(E$3>=Ipotesi!$B$14,Ipotesi!$B$13,0) -> 0.0217 | F19: =Ipotesi!F7+IF(F$3>=Ipotesi!$B$14,Ipotesi!$B$13,0) -> 0.0277 | G19: =Ipotesi!G7+IF(G$3>=Ipotesi!$B$14,Ipotesi!$B$13,0) -> 0.0277 | H19: =Ipotesi!H7+IF(H$3>=Ipotesi!$B$14,Ipotesi!$B$13,0) -> 0.0277 | I19: =Ipotesi!I7+IF(I$3>=Ipotesi!$B$14,Ipotesi!$B$13,0) -> 0.0277
A20: Stock-flussi (SF) | C20: =Ipotesi!C10 -> 0.020938656 | D20: =Ipotesi!D10 -> 0.012920311 | E20: =Ipotesi!E10 -> 0.0023855891 | F20: =Ipotesi!F10 -> -0.0011052632 | G20: =Ipotesi!G10 -> 0 | H20: =Ipotesi!H10 -> 0 | I20: =Ipotesi!I10 -> 0
A21: Debito/PIL fine anno | C21: =C16*(1+C18)/(1+C17)-C19+C20 -> 1.381 | D21: =D16*(1+D18)/(1+D17)-D19+D20 -> 1.384 | E21: =E16*(1+E18)/(1+E17)-E19+E20 -> 1.3743 | F21: =F16*(1+F18)/(1+F17)-F19+F20 -> 1.3575763 | G21: =G16*(1+G18)/(1+G17)-G19+G20 -> 1.3418108 | H21: =H16*(1+H18)/(1+H17)-H19+H20 -> 1.3259067 | I21: =I16*(1+I18)/(1+I17)-I19+I20 -> 1.3098628
A22: Avanzo di stabilizzazione (s*) | C22: =C16*(C18-C17)/(1+C17)+C20 -> 0.026 | D22: =D16*(D18-D17)/(1+D17)+D20 -> 0.017 | E22: =E16*(E18-E17)/(1+E17)+E20 -> 0.012 | F22: =F16*(F18-F17)/(1+F17)+F20 -> 0.010976264 | G22: =G16*(G18-G17)/(1+G17)+G20 -> 0.011934508 | H22: =H16*(H18-H17)/(1+H17)+H20 -> 0.011795913 | I22: =I16*(I18-I17)/(1+I17)+I20 -> 0.0116561
A23: Scarto dal tendenziale (p.p.) | C23: =(C21-C$10)*100 -> 0 | D23: =(D21-D$10)*100 -> 0 | E23: =(E21-E$10)*100 -> -0.27 | F23: =(F21-F$10)*100 -> -0.54237358 | G23: =(G21-G$10)*100 -> -0.81714161 | H23: =(H21-H$10)*100 -> -1.0943251 | I23: =(I21-I$10)*100 -> -1.3739454
A26: 3. Programma + crescita
A27: Debito/PIL inizio anno | C27: =Ipotesi!$B$4 -> 1.367 | D27: =C32 -> 1.381 | E27: =D32 -> 1.384 | F27: =E32 -> 1.3743 | G27: =F32 -> 1.3535343 | H27: =G32 -> 1.3337525 | I27: =H32 -> 1.3138549
A28: Crescita nominale (g) | C28: =Ipotesi!C5+IF(C$3>=Ipotesi!$B$16,Ipotesi!$B$15,0) -> 0.027 | D28: =Ipotesi!D5+IF(D$3>=Ipotesi!$B$16,Ipotesi!$B$15,0) -> 0.029 | E28: =Ipotesi!E5+IF(E$3>=Ipotesi!$B$16,Ipotesi!$B$15,0) -> 0.027 | F28: =Ipotesi!F5+IF(F$3>=Ipotesi!$B$16,Ipotesi!$B$15,0) -> 0.029 | G28: =Ipotesi!G5+IF(G$3>=Ipotesi!$B$16,Ipotesi!$B$15,0) -> 0.029 | H28: =Ipotesi!H5+IF(H$3>=Ipotesi!$B$16,Ipotesi!$B$15,0) -> 0.029 | I28: =Ipotesi!I5+IF(I$3>=Ipotesi!$B$16,Ipotesi!$B$15,0) -> 0.029
A29: Tasso implicito (i) | C29: =Ipotesi!C9 -> 0.030802487 | D29: =Ipotesi!D9 -> 0.032039826 | E29: =Ipotesi!E9 -> 0.034134393 | F29: =Ipotesi!F9 -> 0.035019608 | G29: =Ipotesi!G9 -> 0.035019608 | H29: =Ipotesi!H9 -> 0.035019608 | I29: =Ipotesi!I9 -> 0.035019608
A30: Saldo primario (s) | C30: =Ipotesi!C7+IF(C$3>=Ipotesi!$B$14,Ipotesi!$B$13,0) -> 0.012 | D30: =Ipotesi!D7+IF(D$3>=Ipotesi!$B$14,Ipotesi!$B$13,0) -> 0.014 | E30: =Ipotesi!E7+IF(E$3>=Ipotesi!$B$14,Ipotesi!$B$13,0) -> 0.0217 | F30: =Ipotesi!F7+IF(F$3>=Ipotesi!$B$14,Ipotesi!$B$13,0) -> 0.0277 | G30: =Ipotesi!G7+IF(G$3>=Ipotesi!$B$14,Ipotesi!$B$13,0) -> 0.0277 | H30: =Ipotesi!H7+IF(H$3>=Ipotesi!$B$14,Ipotesi!$B$13,0) -> 0.0277 | I30: =Ipotesi!I7+IF(I$3>=Ipotesi!$B$14,Ipotesi!$B$13,0) -> 0.0277
A31: Stock-flussi (SF) | C31: =Ipotesi!C10 -> 0.020938656 | D31: =Ipotesi!D10 -> 0.012920311 | E31: =Ipotesi!E10 -> 0.0023855891 | F31: =Ipotesi!F10 -> -0.0011052632 | G31: =Ipotesi!G10 -> 0 | H31: =Ipotesi!H10 -> 0 | I31: =Ipotesi!I10 -> 0
A32: Debito/PIL fine anno | C32: =C27*(1+C29)/(1+C28)-C30+C31 -> 1.381 | D32: =D27*(1+D29)/(1+D28)-D30+D31 -> 1.384 | E32: =E27*(1+E29)/(1+E28)-E30+E31 -> 1.3743 | F32: =F27*(1+F29)/(1+F28)-F30+F31 -> 1.3535343 | G32: =G27*(1+G29)/(1+G28)-G30+G31 -> 1.3337525 | H32: =H27*(1+H29)/(1+H28)-H30+H31 -> 1.3138549 | I32: =I27*(1+I29)/(1+I28)-I30+I31 -> 1.2938409
A33: Avanzo di stabilizzazione (s*) | C33: =C27*(C29-C28)/(1+C28)+C31 -> 0.026 | D33: =D27*(D29-D28)/(1+D28)+D31 -> 0.017 | E33: =E27*(E29-E28)/(1+E28)+E31 -> 0.012 | F33: =F27*(F29-F28)/(1+F28)+F31 -> 0.0069343355 | G33: =G27*(G29-G28)/(1+G28)+G31 -> 0.0079181204 | H33: =H27*(H29-H28)/(1+H28)+H31 -> 0.0078023972 | I33: =I27*(I29-I28)/(1+I28)+I31 -> 0.0076859971
A34: Scarto dal tendenziale (p.p.) | C34: =(C32-C$10)*100 -> 0 | D34: =(D32-D$10)*100 -> 0 | E34: =(E32-E$10)*100 -> -0.27 | F34: =(F32-F$10)*100 -> -0.94656645 | G34: =(G32-G$10)*100 -> -1.6229733 | H34: =(H32-H$10)*100 -> -2.2995084 | I34: =(I32-I$10)*100 -> -2.9761389
A37: 4. Stress tassi (su quadro tendenziale)
A38: Debito/PIL inizio anno | C38: =Ipotesi!$B$4 -> 1.367 | D38: =C43 -> 1.381 | E38: =D43 -> 1.384 | F38: =E43 -> 1.3787058 | G38: =F43 -> 1.3681228 | H38: =G43 -> 1.3602137 | I38: =H43 -> 1.3538841
A39: Crescita nominale (g) | C39: =Ipotesi!C5 -> 0.027 | D39: =Ipotesi!D5 -> 0.029 | E39: =Ipotesi!E5 -> 0.027 | F39: =Ipotesi!F5 -> 0.026 | G39: =Ipotesi!G5 -> 0.026 | H39: =Ipotesi!H5 -> 0.026 | I39: =Ipotesi!I5 -> 0.026
A40: Tasso implicito (i) | C40: =Ipotesi!C9+Ipotesi!$B$17*MIN(1,MAX(0,C$3-Ipotesi!$B$18+1)*Ipotesi!$B$20) -> 0.030802487 | D40: =Ipotesi!D9+Ipotesi!$B$17*MIN(1,MAX(0,D$3-Ipotesi!$B$18+1)*Ipotesi!$B$20) -> 0.032039826 | E40: =Ipotesi!E9+Ipotesi!$B$17*MIN(1,MAX(0,E$3-Ipotesi!$B$18+1)*Ipotesi!$B$20) -> 0.035400216 | F40: =Ipotesi!F9+Ipotesi!$B$17*MIN(1,MAX(0,F$3-Ipotesi!$B$18+1)*Ipotesi!$B$20) -> 0.037551253 | G40: =Ipotesi!G9+Ipotesi!$B$17*MIN(1,MAX(0,G$3-Ipotesi!$B$18+1)*Ipotesi!$B$20) -> 0.038817076 | H40: =Ipotesi!H9+Ipotesi!$B$17*MIN(1,MAX(0,H$3-Ipotesi!$B$18+1)*Ipotesi!$B$20) -> 0.040082899 | I40: =Ipotesi!I9+Ipotesi!$B$17*MIN(1,MAX(0,I$3-Ipotesi!$B$18+1)*Ipotesi!$B$20) -> 0.041348722
A41: Saldo primario (s) | C41: =Ipotesi!C7 -> 0.012 | D41: =Ipotesi!D7 -> 0.014 | E41: =Ipotesi!E7 -> 0.019 | F41: =Ipotesi!F7 -> 0.025 | G41: =Ipotesi!G7 -> 0.025 | H41: =Ipotesi!H7 -> 0.025 | I41: =Ipotesi!I7 -> 0.025
A42: Stock-flussi (SF) | C42: =Ipotesi!C10 -> 0.020938656 | D42: =Ipotesi!D10 -> 0.012920311 | E42: =Ipotesi!E10 -> 0.0023855891 | F42: =Ipotesi!F10 -> -0.0011052632 | G42: =Ipotesi!G10 -> 0 | H42: =Ipotesi!H10 -> 0 | I42: =Ipotesi!I10 -> 0
A43: Debito/PIL fine anno | C43: =C38*(1+C40)/(1+C39)-C41+C42 -> 1.381 | D43: =D38*(1+D40)/(1+D39)-D41+D42 -> 1.384 | E43: =E38*(1+E40)/(1+E39)-E41+E42 -> 1.3787058 | F43: =F38*(1+F40)/(1+F39)-F41+F42 -> 1.3681228 | G43: =G38*(1+G40)/(1+G39)-G41+G42 -> 1.3602137 | H43: =H38*(1+H40)/(1+H39)-H41+H42 -> 1.3538841 | I43: =I38*(1+I40)/(1+I39)-I41+I42 -> 1.3491379
A44: Avanzo di stabilizzazione (s*) | C44: =C38*(C40-C39)/(1+C39)+C42 -> 0.026 | D44: =D38*(D40-D39)/(1+D39)+D42 -> 0.017 | E44: =E38*(E40-E39)/(1+E39)+E42 -> 0.013705841 | F44: =F38*(F40-F39)/(1+F39)+F42 -> 0.01441694 | G44: =G38*(G40-G39)/(1+G39)+G42 -> 0.017090969 | H44: =H38*(H40-H39)/(1+H39)+H42 -> 0.018670324 | I44: =I38*(I40-I39)/(1+I39)+I42 -> 0.020253791
A45: Scarto dal tendenziale (p.p.) | C45: =(C43-C$10)*100 -> 0 | D45: =(D43-D$10)*100 -> 0 | E45: =(E43-E$10)*100 -> 0.1705841 | F45: =(F43-F$10)*100 -> 0.51227811 | G45: =(G43-G$10)*100 -> 1.0231561 | H45: =(H43-H$10)*100 -> 1.7034137 | I45: =(I43-I$10)*100 -> 2.5535626
A48: Sintesi | B48: Debito/PIL 2029 | C48: Debito/PIL 2032 | D48: Scarto 2032 (p.p.)
A49: 1. Tendenziale (DPFP 2026 esteso al 2032) | B49: =F10 -> 1.363 | C49: =I10 -> 1.3236022 | D49: =I12 -> 0
...

Sheet Fonti
A1: Fonti
A3: Documento | B3: Riferimento
A4: Documento programmatico di finanza pubblica 2026 (DPFP), trasmesso alle Camere il 2/10/2026 — quadro tendenziale e programmatico | B4: https://documenti.camera.it/leg19/dossier/pdf/gi0117.pdf (dossier Servizio Studi Camera, 7/10/2026)
A5: ISTAT, conti economici nazionali e notifica, 22/9/2026: debito/PIL 2025 rivisto al 136,7% (da 137,1%), 2024 al 134,2% | B5: Citato nel dossier Camera di cui sopra
A6: Banca d'Italia, audizione sul DPFP 2026 (12/10/2026): interessi 4,2% PIL nel 2026, 4,6% nel 2028-29; debito programmatico 136,6% nel 2029 | B6: https://www.teleborsa.it/News/2026/10/12/dpfb-banca-d-italia-alze-le-stime-sul-pil-nel-2026-al-1percent-179.html (resoconto; verificare sul testo integrale Banca d'Italia)
A7: UPB, audizione sul DPFP 2026 (ottobre 2026): scenario UPB con debito al 137,7% nel 2029; con aspettative di mercato aggiornate 138,4% | B7: https://www.teleborsa.it/News/2026/10/12/dfpb-validazione-dell-upb-al-quadro-macro-ma-con-uso-clausola-poco-spazio-per-altre-misure-203.html (resoconto; verificare sul testo integrale UPB)
A8: UPB, audizione sul DFP 2026 (28/4/2026): proventi da privatizzazioni ipotizzati e rischi sulla traiettoria del debito | B8: https://www.upbilancio.it/wp-content/uploads/2026/04/CS_audizione-DFP-2026.pdf
